[2023-12-14T13:57:42.366+0000] {taskinstance.py:1159} INFO - Dependencies all met for dep_context=non-requeueable deps ti=<TaskInstance: first_dag.send_email manual__2023-12-14T13:57:39.573299+00:00 [queued]>
[2023-12-14T13:57:42.373+0000] {taskinstance.py:1159} INFO - Dependencies all met for dep_context=requeueable deps ti=<TaskInstance: first_dag.send_email manual__2023-12-14T13:57:39.573299+00:00 [queued]>
[2023-12-14T13:57:42.373+0000] {taskinstance.py:1361} INFO - Starting attempt 1 of 1
[2023-12-14T13:57:42.385+0000] {taskinstance.py:1382} INFO - Executing <Task(PythonOperator): send_email> on 2023-12-14 13:57:39.573299+00:00
[2023-12-14T13:57:42.390+0000] {standard_task_runner.py:57} INFO - Started process 65 to run task
[2023-12-14T13:57:42.392+0000] {standard_task_runner.py:84} INFO - Running: ['***', 'tasks', 'run', 'first_dag', 'send_email', 'manual__2023-12-14T13:57:39.573299+00:00', '--job-id', '17', '--raw', '--subdir', 'DAGS_FOLDER/first_dag.py', '--cfg-path', '/tmp/tmpi26beamz']
[2023-12-14T13:57:42.395+0000] {standard_task_runner.py:85} INFO - Job 17: Subtask send_email
[2023-12-14T13:57:42.432+0000] {task_command.py:416} INFO - Running <TaskInstance: first_dag.send_email manual__2023-12-14T13:57:39.573299+00:00 [running]> on host 5f3142086985
[2023-12-14T13:57:42.495+0000] {taskinstance.py:1662} INFO - Exporting env vars: AIRFLOW_CTX_DAG_OWNER='***' AIRFLOW_CTX_DAG_ID='first_dag' AIRFLOW_CTX_TASK_ID='send_email' AIRFLOW_CTX_EXECUTION_DATE='2023-12-14T13:57:39.573299+00:00' AIRFLOW_CTX_TRY_NUMBER='1' AIRFLOW_CTX_DAG_RUN_ID='manual__2023-12-14T13:57:39.573299+00:00'
[2023-12-14T13:57:42.497+0000] {taskinstance.py:1937} ERROR - Task failed with exception
Traceback (most recent call last):
  File "/home/airflow/.local/lib/python3.8/site-packages/airflow/operators/python.py", line 192, in execute
    return_value = self.execute_callable()
  File "/home/airflow/.local/lib/python3.8/site-packages/airflow/operators/python.py", line 209, in execute_callable
    return self.python_callable(*self.op_args, **self.op_kwargs)
  File "/opt/airflow/dags/first_dag.py", line 19, in send_email
    conn = psycopg2.connect(
  File "/home/airflow/.local/lib/python3.8/site-packages/psycopg2/__init__.py", line 122, in connect
    conn = _connect(dsn, connection_factory=connection_factory, **kwasync)
psycopg2.OperationalError: connection to server at "localhost" (127.0.0.1), port 5432 failed: Connection refused
	Is the server running on that host and accepting TCP/IP connections?
connection to server at "localhost" (::1), port 5432 failed: Cannot assign requested address
	Is the server running on that host and accepting TCP/IP connections?

[2023-12-14T13:57:42.505+0000] {taskinstance.py:1400} INFO - Marking task as FAILED. dag_id=first_dag, task_id=send_email, execution_date=20231214T135739, start_date=20231214T135742, end_date=20231214T135742
[2023-12-14T13:57:42.514+0000] {standard_task_runner.py:104} ERROR - Failed to execute job 17 for task send_email (connection to server at "localhost" (127.0.0.1), port 5432 failed: Connection refused
	Is the server running on that host and accepting TCP/IP connections?
connection to server at "localhost" (::1), port 5432 failed: Cannot assign requested address
	Is the server running on that host and accepting TCP/IP connections?
; 65)
[2023-12-14T13:57:42.524+0000] {local_task_job_runner.py:228} INFO - Task exited with return code 1
[2023-12-14T13:57:42.538+0000] {taskinstance.py:2778} INFO - 0 downstream tasks scheduled from follow-on schedule check
