[2023-12-15T13:50:26.760+0000] {taskinstance.py:1159} INFO - Dependencies all met for dep_context=non-requeueable deps ti=<TaskInstance: first_dag.send_email manual__2023-12-15T13:50:24.863143+00:00 [queued]>
[2023-12-15T13:50:26.769+0000] {taskinstance.py:1159} INFO - Dependencies all met for dep_context=requeueable deps ti=<TaskInstance: first_dag.send_email manual__2023-12-15T13:50:24.863143+00:00 [queued]>
[2023-12-15T13:50:26.770+0000] {taskinstance.py:1361} INFO - Starting attempt 1 of 1
[2023-12-15T13:50:26.782+0000] {taskinstance.py:1382} INFO - Executing <Task(PythonOperator): send_email> on 2023-12-15 13:50:24.863143+00:00
[2023-12-15T13:50:26.787+0000] {standard_task_runner.py:57} INFO - Started process 3581 to run task
[2023-12-15T13:50:26.789+0000] {standard_task_runner.py:84} INFO - Running: ['airflow', 'tasks', 'run', 'first_dag', 'send_email', 'manual__2023-12-15T13:50:24.863143+00:00', '--job-id', '26', '--raw', '--subdir', 'DAGS_FOLDER/first_dag.py', '--cfg-path', '/tmp/tmpyxm6znuy']
[2023-12-15T13:50:26.791+0000] {standard_task_runner.py:85} INFO - Job 26: Subtask send_email
[2023-12-15T13:50:26.954+0000] {task_command.py:416} INFO - Running <TaskInstance: first_dag.send_email manual__2023-12-15T13:50:24.863143+00:00 [running]> on host ef1922c04df9
[2023-12-15T13:50:27.306+0000] {taskinstance.py:1662} INFO - Exporting env vars: AIRFLOW_CTX_DAG_OWNER='airflow' AIRFLOW_CTX_DAG_ID='first_dag' AIRFLOW_CTX_TASK_ID='send_email' AIRFLOW_CTX_EXECUTION_DATE='2023-12-15T13:50:24.863143+00:00' AIRFLOW_CTX_TRY_NUMBER='1' AIRFLOW_CTX_DAG_RUN_ID='manual__2023-12-15T13:50:24.863143+00:00'
[2023-12-15T13:50:27.308+0000] {taskinstance.py:1937} ERROR - Task failed with exception
Traceback (most recent call last):
  File "/home/airflow/.local/lib/python3.8/site-packages/airflow/operators/python.py", line 192, in execute
    return_value = self.execute_callable()
  File "/home/airflow/.local/lib/python3.8/site-packages/airflow/operators/python.py", line 209, in execute_callable
    return self.python_callable(*self.op_args, **self.op_kwargs)
TypeError: connect() missing 1 required positional argument: 'order_id'
[2023-12-15T13:50:27.352+0000] {taskinstance.py:1400} INFO - Marking task as FAILED. dag_id=first_dag, task_id=send_email, execution_date=20231215T135024, start_date=20231215T135026, end_date=20231215T135027
[2023-12-15T13:50:27.369+0000] {standard_task_runner.py:104} ERROR - Failed to execute job 26 for task send_email (connect() missing 1 required positional argument: 'order_id'; 3581)
[2023-12-15T13:50:27.403+0000] {local_task_job_runner.py:228} INFO - Task exited with return code 1
[2023-12-15T13:50:27.466+0000] {taskinstance.py:2778} INFO - 0 downstream tasks scheduled from follow-on schedule check
