[2023-12-18T09:12:08.399+0000] {taskinstance.py:1159} INFO - Dependencies all met for dep_context=non-requeueable deps ti=<TaskInstance: first_dag.send_email scheduled__2023-12-16T11:03:55.446713+00:00 [queued]>
[2023-12-18T09:12:08.415+0000] {taskinstance.py:1159} INFO - Dependencies all met for dep_context=requeueable deps ti=<TaskInstance: first_dag.send_email scheduled__2023-12-16T11:03:55.446713+00:00 [queued]>
[2023-12-18T09:12:08.416+0000] {taskinstance.py:1361} INFO - Starting attempt 1 of 1
[2023-12-18T09:12:08.441+0000] {taskinstance.py:1382} INFO - Executing <Task(PythonOperator): send_email> on 2023-12-16 11:03:55.446713+00:00
[2023-12-18T09:12:08.449+0000] {standard_task_runner.py:57} INFO - Started process 57 to run task
[2023-12-18T09:12:08.454+0000] {standard_task_runner.py:84} INFO - Running: ['airflow', 'tasks', 'run', 'first_dag', 'send_email', 'scheduled__2023-12-16T11:03:55.446713+00:00', '--job-id', '45', '--raw', '--subdir', 'DAGS_FOLDER/first_dag.py', '--cfg-path', '/tmp/tmpxgzo2ac9']
[2023-12-18T09:12:08.458+0000] {standard_task_runner.py:85} INFO - Job 45: Subtask send_email
[2023-12-18T09:12:08.958+0000] {task_command.py:416} INFO - Running <TaskInstance: first_dag.send_email scheduled__2023-12-16T11:03:55.446713+00:00 [running]> on host ef1922c04df9
[2023-12-18T09:12:09.323+0000] {taskinstance.py:1662} INFO - Exporting env vars: AIRFLOW_CTX_DAG_OWNER='airflow' AIRFLOW_CTX_DAG_ID='first_dag' AIRFLOW_CTX_TASK_ID='send_email' AIRFLOW_CTX_EXECUTION_DATE='2023-12-16T11:03:55.446713+00:00' AIRFLOW_CTX_TRY_NUMBER='1' AIRFLOW_CTX_DAG_RUN_ID='scheduled__2023-12-16T11:03:55.446713+00:00'
[2023-12-18T09:12:09.325+0000] {taskinstance.py:1937} ERROR - Task failed with exception
Traceback (most recent call last):
  File "/home/airflow/.local/lib/python3.8/site-packages/airflow/operators/python.py", line 192, in execute
    return_value = self.execute_callable()
  File "/home/airflow/.local/lib/python3.8/site-packages/airflow/operators/python.py", line 209, in execute_callable
    return self.python_callable(*self.op_args, **self.op_kwargs)
TypeError: connect() missing 1 required positional argument: 'order_id'
[2023-12-18T09:12:09.374+0000] {taskinstance.py:1400} INFO - Marking task as FAILED. dag_id=first_dag, task_id=send_email, execution_date=20231216T110355, start_date=20231218T091208, end_date=20231218T091209
[2023-12-18T09:12:09.391+0000] {standard_task_runner.py:104} ERROR - Failed to execute job 45 for task send_email (connect() missing 1 required positional argument: 'order_id'; 57)
[2023-12-18T09:12:09.430+0000] {local_task_job_runner.py:228} INFO - Task exited with return code 1
[2023-12-18T09:12:09.485+0000] {taskinstance.py:2778} INFO - 0 downstream tasks scheduled from follow-on schedule check
