[2023-12-15T11:11:23.754+0000] {taskinstance.py:1159} INFO - Dependencies all met for dep_context=non-requeueable deps ti=<TaskInstance: first_dag.send_email manual__2023-12-15T11:11:21.668202+00:00 [queued]>
[2023-12-15T11:11:23.764+0000] {taskinstance.py:1159} INFO - Dependencies all met for dep_context=requeueable deps ti=<TaskInstance: first_dag.send_email manual__2023-12-15T11:11:21.668202+00:00 [queued]>
[2023-12-15T11:11:23.764+0000] {taskinstance.py:1361} INFO - Starting attempt 1 of 1
[2023-12-15T11:11:23.779+0000] {taskinstance.py:1382} INFO - Executing <Task(PythonOperator): send_email> on 2023-12-15 11:11:21.668202+00:00
[2023-12-15T11:11:23.784+0000] {standard_task_runner.py:57} INFO - Started process 1151 to run task
[2023-12-15T11:11:23.786+0000] {standard_task_runner.py:84} INFO - Running: ['airflow', 'tasks', 'run', 'first_dag', 'send_email', 'manual__2023-12-15T11:11:21.668202+00:00', '--job-id', '20', '--raw', '--subdir', 'DAGS_FOLDER/first_dag.py', '--cfg-path', '/tmp/tmpgo69jht7']
[2023-12-15T11:11:23.789+0000] {standard_task_runner.py:85} INFO - Job 20: Subtask send_email
[2023-12-15T11:11:24.071+0000] {task_command.py:416} INFO - Running <TaskInstance: first_dag.send_email manual__2023-12-15T11:11:21.668202+00:00 [running]> on host ef1922c04df9
[2023-12-15T11:11:24.320+0000] {taskinstance.py:1662} INFO - Exporting env vars: AIRFLOW_CTX_DAG_OWNER='airflow' AIRFLOW_CTX_DAG_ID='first_dag' AIRFLOW_CTX_TASK_ID='send_email' AIRFLOW_CTX_EXECUTION_DATE='2023-12-15T11:11:21.668202+00:00' AIRFLOW_CTX_TRY_NUMBER='1' AIRFLOW_CTX_DAG_RUN_ID='manual__2023-12-15T11:11:21.668202+00:00'
[2023-12-15T11:11:24.363+0000] {taskinstance.py:1937} ERROR - Task failed with exception
Traceback (most recent call last):
  File "/home/airflow/.local/lib/python3.8/site-packages/airflow/operators/python.py", line 192, in execute
    return_value = self.execute_callable()
  File "/home/airflow/.local/lib/python3.8/site-packages/airflow/operators/python.py", line 209, in execute_callable
    return self.python_callable(*self.op_args, **self.op_kwargs)
  File "/opt/airflow/dags/first_dag.py", line 42, in connect
    'phone': item[9],
IndexError: tuple index out of range
[2023-12-15T11:11:24.409+0000] {taskinstance.py:1400} INFO - Marking task as FAILED. dag_id=first_dag, task_id=send_email, execution_date=20231215T111121, start_date=20231215T111123, end_date=20231215T111124
[2023-12-15T11:11:24.425+0000] {standard_task_runner.py:104} ERROR - Failed to execute job 20 for task send_email (tuple index out of range; 1151)
[2023-12-15T11:11:24.440+0000] {local_task_job_runner.py:228} INFO - Task exited with return code 1
[2023-12-15T11:11:24.494+0000] {taskinstance.py:2778} INFO - 0 downstream tasks scheduled from follow-on schedule check
