[2023-12-14T13:54:13.181+0000] {taskinstance.py:1159} INFO - Dependencies all met for dep_context=non-requeueable deps ti=<TaskInstance: first_dag.send_email manual__2023-12-14T13:54:11.951204+00:00 [queued]>
[2023-12-14T13:54:13.188+0000] {taskinstance.py:1159} INFO - Dependencies all met for dep_context=requeueable deps ti=<TaskInstance: first_dag.send_email manual__2023-12-14T13:54:11.951204+00:00 [queued]>
[2023-12-14T13:54:13.188+0000] {taskinstance.py:1361} INFO - Starting attempt 1 of 1
[2023-12-14T13:54:13.200+0000] {taskinstance.py:1382} INFO - Executing <Task(PythonOperator): send_email> on 2023-12-14 13:54:11.951204+00:00
[2023-12-14T13:54:13.205+0000] {standard_task_runner.py:57} INFO - Started process 821 to run task
[2023-12-14T13:54:13.207+0000] {standard_task_runner.py:84} INFO - Running: ['***', 'tasks', 'run', 'first_dag', 'send_email', 'manual__2023-12-14T13:54:11.951204+00:00', '--job-id', '14', '--raw', '--subdir', 'DAGS_FOLDER/first_dag.py', '--cfg-path', '/tmp/tmp9vxe0iys']
[2023-12-14T13:54:13.210+0000] {standard_task_runner.py:85} INFO - Job 14: Subtask send_email
[2023-12-14T13:54:13.253+0000] {task_command.py:416} INFO - Running <TaskInstance: first_dag.send_email manual__2023-12-14T13:54:11.951204+00:00 [running]> on host e5d91e036e1c
[2023-12-14T13:54:13.319+0000] {taskinstance.py:1662} INFO - Exporting env vars: AIRFLOW_CTX_DAG_OWNER='***' AIRFLOW_CTX_DAG_ID='first_dag' AIRFLOW_CTX_TASK_ID='send_email' AIRFLOW_CTX_EXECUTION_DATE='2023-12-14T13:54:11.951204+00:00' AIRFLOW_CTX_TRY_NUMBER='1' AIRFLOW_CTX_DAG_RUN_ID='manual__2023-12-14T13:54:11.951204+00:00'
[2023-12-14T13:54:13.321+0000] {taskinstance.py:1937} ERROR - Task failed with exception
Traceback (most recent call last):
  File "/home/airflow/.local/lib/python3.8/site-packages/airflow/operators/python.py", line 192, in execute
    return_value = self.execute_callable()
  File "/home/airflow/.local/lib/python3.8/site-packages/airflow/operators/python.py", line 209, in execute_callable
    return self.python_callable(*self.op_args, **self.op_kwargs)
  File "/opt/airflow/dags/first_dag.py", line 19, in send_email
    conn = psycopg2.connect(
  File "/home/airflow/.local/lib/python3.8/site-packages/psycopg2/__init__.py", line 122, in connect
    conn = _connect(dsn, connection_factory=connection_factory, **kwasync)
psycopg2.OperationalError: connection to server at "localhost" (127.0.0.1), port 5432 failed: Connection refused
	Is the server running on that host and accepting TCP/IP connections?
connection to server at "localhost" (::1), port 5432 failed: Cannot assign requested address
	Is the server running on that host and accepting TCP/IP connections?

[2023-12-14T13:54:13.332+0000] {taskinstance.py:1400} INFO - Marking task as FAILED. dag_id=first_dag, task_id=send_email, execution_date=20231214T135411, start_date=20231214T135413, end_date=20231214T135413
[2023-12-14T13:54:13.343+0000] {standard_task_runner.py:104} ERROR - Failed to execute job 14 for task send_email (connection to server at "localhost" (127.0.0.1), port 5432 failed: Connection refused
	Is the server running on that host and accepting TCP/IP connections?
connection to server at "localhost" (::1), port 5432 failed: Cannot assign requested address
	Is the server running on that host and accepting TCP/IP connections?
; 821)
[2023-12-14T13:54:13.380+0000] {local_task_job_runner.py:228} INFO - Task exited with return code 1
[2023-12-14T13:54:13.394+0000] {taskinstance.py:2778} INFO - 0 downstream tasks scheduled from follow-on schedule check
