[2023-12-15T13:50:50.153+0000] {taskinstance.py:1159} INFO - Dependencies all met for dep_context=non-requeueable deps ti=<TaskInstance: first_dag.send_email manual__2023-12-15T13:50:48.250160+00:00 [queued]>
[2023-12-15T13:50:50.165+0000] {taskinstance.py:1159} INFO - Dependencies all met for dep_context=requeueable deps ti=<TaskInstance: first_dag.send_email manual__2023-12-15T13:50:48.250160+00:00 [queued]>
[2023-12-15T13:50:50.166+0000] {taskinstance.py:1361} INFO - Starting attempt 1 of 1
[2023-12-15T13:50:50.183+0000] {taskinstance.py:1382} INFO - Executing <Task(PythonOperator): send_email> on 2023-12-15 13:50:48.250160+00:00
[2023-12-15T13:50:50.188+0000] {standard_task_runner.py:57} INFO - Started process 3592 to run task
[2023-12-15T13:50:50.191+0000] {standard_task_runner.py:84} INFO - Running: ['airflow', 'tasks', 'run', 'first_dag', 'send_email', 'manual__2023-12-15T13:50:48.250160+00:00', '--job-id', '27', '--raw', '--subdir', 'DAGS_FOLDER/first_dag.py', '--cfg-path', '/tmp/tmpv_3a5nut']
[2023-12-15T13:50:50.194+0000] {standard_task_runner.py:85} INFO - Job 27: Subtask send_email
[2023-12-15T13:50:50.584+0000] {task_command.py:416} INFO - Running <TaskInstance: first_dag.send_email manual__2023-12-15T13:50:48.250160+00:00 [running]> on host ef1922c04df9
[2023-12-15T13:50:50.927+0000] {taskinstance.py:1662} INFO - Exporting env vars: AIRFLOW_CTX_DAG_OWNER='airflow' AIRFLOW_CTX_DAG_ID='first_dag' AIRFLOW_CTX_TASK_ID='send_email' AIRFLOW_CTX_EXECUTION_DATE='2023-12-15T13:50:48.250160+00:00' AIRFLOW_CTX_TRY_NUMBER='1' AIRFLOW_CTX_DAG_RUN_ID='manual__2023-12-15T13:50:48.250160+00:00'
[2023-12-15T13:50:51.078+0000] {taskinstance.py:1937} ERROR - Task failed with exception
Traceback (most recent call last):
  File "/home/airflow/.local/lib/python3.8/site-packages/airflow/operators/python.py", line 192, in execute
    return_value = self.execute_callable()
  File "/home/airflow/.local/lib/python3.8/site-packages/airflow/operators/python.py", line 209, in execute_callable
    return self.python_callable(*self.op_args, **self.op_kwargs)
  File "/opt/airflow/dags/first_dag.py", line 28, in connect
    cursor.execute(
psycopg2.errors.UndefinedColumn: ОШИБКА:  столбец "id_" не существует
LINE 12:             WHERE id_ = 16
                           ^

[2023-12-15T13:50:51.130+0000] {taskinstance.py:1400} INFO - Marking task as FAILED. dag_id=first_dag, task_id=send_email, execution_date=20231215T135048, start_date=20231215T135050, end_date=20231215T135051
[2023-12-15T13:50:51.152+0000] {standard_task_runner.py:104} ERROR - Failed to execute job 27 for task send_email (ОШИБКА:  столбец "id_" не существует
LINE 12:             WHERE id_ = 16
                           ^
; 3592)
[2023-12-15T13:50:51.166+0000] {local_task_job_runner.py:228} INFO - Task exited with return code 1
[2023-12-15T13:50:51.334+0000] {taskinstance.py:2778} INFO - 0 downstream tasks scheduled from follow-on schedule check
